Workbook

Sheet 00 Cover
C2: NEXT plc
C3: Three-statement financial model
C5: Author | D5: Obinna Okey-Udeji
C6: Model completed | D6: 46273
C7: Financial information through | D7: 46239
C8: Forecast period | D8: FY2027E–FY2031E
C9: Scenario | D9: Base Case
C10: Currency and units | D10: GBP, £m except where stated
C11: Version | D11: 1.0 — public model
C12: Accounting checks | D12: ='04 Audit & Sources'!E6 -> PASS
C14: Purpose: explain NEXT’s historical performance and a five-year base-case forecast through linked income, cash-flow and balance-sheet statements.
C16: Sources: January 2024–2026 annual reports and results, plus the 5 August 2026 Q2 trading statement. Later disclosures have not been incorporated.
C18: 1. Review the key forecast drivers
C19: 2. Read the three financial statements
C20: 3. Trace the supporting schedules
C21: 4. Review checks, assumptions and sources
C23: Update blue input cells, recalculate, then review the Audit status. Formulas use black text on the same sheet and green for links; outputs on this Cover are dark. Pale amber identifies editable forecast inputs.
C26: Financial development
C27: £m unless stated | D27: FY2023A | E27: FY2024A | F27: FY2025A | G27: FY2026A | H27: FY2027E | I27: FY2028E | J27: FY2029E | K27: FY2030E | L27: FY2031E
C28: Revenue | D28: ='02 Model'!D8 -> 5034 | E28: ='02 Model'!E8 -> 5491 | F28: ='02 Model'!F8 -> 6118.1 | G28: ='02 Model'!G8 -> 6901.3 | H28: ='02 Model'!H8 -> 7265.621 | I28: ='02 Model'!I8 -> 7701.5583 | J28: ='02 Model'!J8 -> 8125.144 | K28: ='02 Model'!K8 -> 8531.4012 | L28: ='02 Model'!L8 -> 8915.3142
C29: Statutory revenue growth | D29: ="n.a." -> n.a. | E29: ='02 Model'!E8/'02 Model'!D8-1 -> 0.090782678 | F29: ='02 Model'!F8/'02 Model'!E8-1 -> 0.11420506 | G29: ='02 Model'!G8/'02 Model'!F8-1 -> 0.1280136 | H29: ='02 Model'!H8/'02 Model'!G8-1 -> 0.052790199 | I29: ='02 Model'!I8/'02 Model'!H8-1 -> 0.06 | J29: ='02 Model'!J8/'02 Model'!I8-1 -> 0.055 | K29: ='02 Model'!K8/'02 Model'!J8-1 -> 0.05 | L29: ='02 Model'!L8/'02 Model'!K8-1 -> 0.045
C30: Operating margin | D30: ='02 Model'!D24/'02 Model'!D8 -> 0.18702821 | E30: ='02 Model'!E24/'02 Model'!E8 -> 0.17991258 | F30: ='02 Model'!F24/'02 Model'!F8 -> 0.17577352 | G30: ='02 Model'!G24/'02 Model'!G8 -> 0.18529842 | H30: ='02 Model'!H24/'02 Model'!H8 -> 0.18334839 | I30: ='02 Model'!I24/'02 Model'!I8 -> 0.18437695 | J30: ='02 Model'!J24/'02 Model'!J8 -> 0.18490003 | K30: ='02 Model'!K24/'02 Model'!K8 -> 0.18491761 | L30: ='02 Model'!L24/'02 Model'!L8 -> 0.18542967
C31: PBT margin | D31: ='02 Model'!D28/'02 Model'!D8 -> 0.17268574 | E31: ='02 Model'!E28/'02 Model'!E8 -> 0.18499363 | F31: ='02 Model'!F28/'02 Model'!F8 -> 0.16132459 | G31: ='02 Model'!G28/'02 Model'!G8 -> 0.17280802 | H31: ='02 Model'!H28/'02 Model'!H8 -> 0.17175807 | I31: ='02 Model'!I28/'02 Model'!I8 -> 0.17445065 | J31: ='02 Model'!J28/'02 Model'!J8 -> 0.17563424 | K31: ='02 Model'!K28/'02 Model'!K8 -> 0.17633022 | L31: ='02 Model'!L28/'02 Model'!L8 -> 0.17743493
C32: Profit before tax | D32: ='02 Model'!D28 -> 869.3 | E32: ='02 Model'!E28 -> 1015.8 | F32: ='02 Model'!F28 -> 987 | G32: ='02 Model'!G28 -> 1192.6 | H32: ='02 Model'!H28 -> 1247.929 | I32: ='02 Model'!I28 -> 1343.5418 | J32: ='02 Model'!J28 -> 1427.0535 | K32: ='02 Model'!K28 -> 1504.3439 | L32: ='02 Model'!L28 -> 1581.8882
C33: Total cash capex | D33: =-'02 Model'!D102-'02 Model'!D106 -> 246.1 | E33: =-'02 Model'!E102-'02 Model'!E106 -> 188.2 | F33: =-'02 Model'!F102-'02 Model'!F106 -> 157.5 | G33: =-'02 Model'!G102-'02 Model'!G106 -> 171.2 | H33: =-'02 Model'!H102-'02 Model'!H106 -> 237 | I33: =-'02 Model'!I102-'02 Model'!I106 -> 252 | J33: =-'02 Model'!J102-'02 Model'!J106 -> 227 | K33: =-'02 Model'!K102-'02 Model'!K106 -> 289 | L33: =-'02 Model'!L102-'02 Model'!L106 -> 300
C34: Free cash flow after capex, interest and leases | D34: ='02 Model'!D99+'02 Model'!D102+'02 Model'!D106+'02 Model'!D122+'02 Model'!D123 -> 321.5 | E34: ='02 Model'!E99+'02 Model'!E102+'02 Model'!E106+'02 Model'!E122+'02 Model'!E123 -> 696.8 | F34: ='02 Model'!F99+'02 Model'!F102+'02 Model'!F106+'02 Model'!F122+'02 Model'!F123 -> 718.5 | G34: ='02 Model'!G99+'02 Model'!G102+'02 Model'!G106+'02 Model'!G122+'02 Model'!G123 -> 800.9 | H34: ='02 Model'!H99+'02 Model'!H102+'02 Model'!H106+'02 Model'!H122+'02 Model'!H123 -> 1042.9482 | I34: ='02 Model'!I99+'02 Model'!I102+'02 Model'!I106+'02 Model'!I122+'02 Model'!I123 -> 864.89327 | J34: ='02 Model'!J99+'02 Model'!J102+'02 Model'!J106+'02 Model'!J122+'02 Model'!J123 -> 1118.2097 | K34: ='02 Model'!K99+'02 Model'!K102+'02 Model'!K106+'02 Model'!K122+'02 Model'!K123 -> 971.15077 | L34: ='02 Model'!L99+'02 Model'!L102+'02 Model'!L106+'02 Model'!L122+'02 Model'!L123 -> 1193.1848
C35: Net debt excluding leases (cash equivalents) | D35: ='03 Schedules'!D161 -> 788 | E35: ='03 Schedules'!E161 -> 690.7 | F35: ='03 Schedules'!F161 -> 654 | G35: ='03 Schedules'!G161 -> 712.7 | H35: ='03 Schedules'!H161 -> 620.25185 | I35: ='03 Schedules'!I161 -> 632 | J35: ='03 Schedules'!J161 -> 632 | K35: ='03 Schedules'!K161 -> 632 | L35: ='03 Schedules'!L161 -> 632
C36: Ordinary dividends paid | D36: =-'02 Model'!D129 -> 237.4 | E36: =-'02 Model'!E129 -> 248.3 | F36: =-'02 Model'!F129 -> 257.8 | G36: =-'02 Model'!G129 -> 286.5 | H36: =-'02 Model'!H129 -> 318 | I36: =-'02 Model'!I129 -> 340.4 | J36: =-'02 Model'!J129 -> 374.1 | K36: =-'02 Model'!K129 -> 396.1 | L36: =-'02 Model'!L129 -> 417.2
C37: Non-ordinary shareholder returns | D37: =-'02 Model'!D114-'02 Model'!D128 -> 228.5 | E37: =-'02 Model'!E114-'02 Model'!E128 -> 177.3 | F37: =-'02 Model'!F114-'02 Model'!F128 -> 360.2 | G37: =-'02 Model'!G114-'02 Model'!G128 -> 552.9 | H37: =-'02 Model'!H114-'02 Model'!H128 -> 524 | I37: =-'02 Model'!I114-'02 Model'!I128 -> 461.48248 | J37: =-'02 Model'!J114-'02 Model'!J128 -> 665.86848 | K37: =-'02 Model'!K114-'02 Model'!K128 -> 493.36318 | L37: =-'02 Model'!L114-'02 Model'!L128 -> 690.84942
C39: Free cash flow here means operating cash after tax, cash capex, borrowing interest and lease payments. It excludes acquisitions and shareholder returns. Net debt excludes lease liabilities and uses cash equivalents.
C41: FY2027 reported revenue growth includes the effect of removing FY2026’s 53rd week; the forecast input is 7% growth on the comparable 52-week base.
N44: Period | O44: Operating margin | P44: PBT margin
N45: =D27 -> FY2023A | O45: =D30 -> 0.18702821 | P45: =D31 -> 0.17268574
N46: =E27 -> FY2024A | O46: =E30 -> 0.17991258 | P46: =E31 -> 0.18499363
N47: =F27 -> FY2025A | O47: =F30 -> 0.17577352 | P47: =F31 -> 0.16132459
N48: =G27 -> FY2026A | O48: =G30 -> 0.18529842 | P48: =G31 -> 0.17280802
N49: =H27 -> FY2027E | O49: =H30 -> 0.18334839 | P49: =H31 -> 0.17175807
N50: =I27 -> FY2028E | O50: =I30 -> 0.18437695 | P50: =I31 -> 0.17445065
N51: =J27 -> FY2029E | O51: =J30 -> 0.18490003 | P51: =J31 -> 0.17563424
N52: =K27 -> FY2030E | O52: =K30 -> 0.18491761 | P52: =K31 -> 0.17633022
...

Sheet 01 Assumptions
C2: Forecast assumptions
C4: Return to Cover
C5: £m except percentages, days and per-share data
D6: FY2023A | E6: FY2024A | F6: FY2025A | G6: FY2026A | H6: FY2027E | I6: FY2028E | J6: FY2029E | K6: FY2030E | L6: FY2031E
C8: Operating performance
C9: Revenue growth | H9: 0.07 | I9: 0.06 | J9: 0.055 | K9: 0.05 | L9: 0.045 | N9: A005
C10: Cost of sales / Revenue | H10: 0.557 | I10: 0.558 | J10: 0.559 | K10: 0.56 | L10: 0.56 | N10: A006
C11: Distribution costs / Revenue | H11: 0.148 | I11: 0.147 | J11: 0.1465 | K11: 0.146 | L11: 0.146 | N11: A007
C12: Administrative expenses / Revenue | H12: 0.11 | I12: 0.109 | J12: 0.108 | K12: 0.1075 | L12: 0.107 | N12: A008
C13: Receivables impairment expense (£m) | H13: 20 | I13: 21 | J13: 22 | K13: 23 | L13: 24 | N13: A085
C14: Share of associates and JVs (£m) | H14: 8 | I14: 8.5 | J14: 9 | K14: 9.5 | L14: 10 | N14: A086
C16: Working capital and customer credit
C17: Inventory days | H17: 86 | I17: 86 | J17: 86 | K17: 86 | L17: 86 | N17: A070
C18: Payables days | H18: 33 | I18: 33 | J18: 33 | K18: 33 | L18: 33 | N18: A021
C19: Customer-credit-book growth | H19: n.a. | I19: 0.02 | J19: 0.02 | K19: 0.02 | L19: 0.02 | N19: A088
C20: Prepayments / Revenue | H20: 0.011 | I20: 0.011 | J20: 0.011 | K20: 0.011 | L20: 0.011 | N20: A014
C21: Other creditors & accruals / Revenue | H21: 0.072 | I21: 0.072 | J21: 0.072 | K21: 0.072 | L21: 0.072 | N21: A023
C23: CapEx and investment
C24: Total cash capex (£m) | H24: 237 | I24: 252 | J24: 227 | K24: 289 | L24: 300 | N24: A126
C25: Intangible additions (£m) | H25: 29 | I25: 32 | J25: 32 | K25: 32 | L25: 32 | N25: A012
C27: Leases
C28: ROU new lease additions (£m) | H28: 120 | I28: 125 | J28: 130 | K28: 135 | L28: 140 | N28: A062
C29: Lease payments (£m) | H29: 225 | I29: 230 | J29: 235 | K29: 240 | L29: 245 | N29: A035
C30: Lease interest rate | H30: 0.055 | I30: 0.053 | J30: 0.051 | K30: 0.05 | L30: 0.05 | N30: A029
C32: Financing and interest
C33: Minimum balance-sheet cash (£m) | H33: n.a. | I33: 100 | J33: 100 | K33: 100 | L33: 100 | N33: A090
C34: Bank loans & overdrafts — closing balance (£m) | H34: 96 | I34: 96 | J34: 96 | K34: 96 | L34: 96 | N34: A058
C35: bank / RCF / overdraft rate (%) | H35: 0.05 | I35: 0.05 | J35: 0.05 | K35: 0.05 | L35: 0.05 | N35: A079
C36: Cash yield (%) | H36: 0.035 | I36: 0.0325 | J36: 0.03 | K36: 0.03 | L36: 0.03 | N36: A046
C37: Refinancing rate | H37: n.a. | I37: 0.045 | J37: 0.045 | K37: 0.045 | L37: 0.045 | N37: A093
C38: 2028 bond refinancing proceeds (£m) | H38: 0 | I38: 0 | J38: 300 | K38: 0 | L38: 0 | N38: A092
C39: RCF renewal / replacement assumed (1 = yes) | H39: 1 | I39: 1 | J39: 1 | K39: 1 | L39: 1 | N39: A095
C41: Tax
C42: Tax rate | H42: 0.25 | I42: 0.25 | J42: 0.25 | K42: 0.25 | L42: 0.25 | N42: A009
C44: Dividends, buybacks and capital allocation
C45: Economic dividend payout | H45: 0.36 | I45: 0.36 | J45: 0.36 | K45: 0.36 | L45: 0.36 | N45: A089
C46: Cash dividends paid (£m) | H46: 318 | I46: 340.4 | J46: 374.1 | K46: 396.1 | L46: 417.2 | N46: A087
C47: Average buyback price (£/share) | H47: n.a. | I47: 140 | J47: 147 | K47: 154 | L47: 162 | N47: A091
C48: NCI dividend payout | H48: n.a. | I48: 0.7 | J48: 0.7 | K48: 0.7 | L48: 0.7 | N48: A096
C49: ERR condition assumed satisfied (1 = yes) | H49: 1 | I49: 1 | J49: 1 | K49: 1 | L49: 1 | N49: A121
...

Sheet 02 Model
C2: Financial statements
C4: Return to Cover
C5: £m. Liabilities and cash outflows are negative.
D6: FY2023A | E6: FY2024A | F6: FY2025A | G6: FY2026A | H6: FY2027E | I6: FY2028E | J6: FY2029E | K6: FY2030E | L6: FY2031E
C7: INCOME STATEMENT | N7: Earnings calculation
C8: Revenue | D8: 5034 | E8: 5491 | F8: 6118.1 | G8: 6901.3 | H8: ='03 Schedules'!H362 -> 7265.621 | I8: ='03 Schedules'!I362 -> 7701.5583 | J8: ='03 Schedules'!J362 -> 8125.144 | K8: ='03 Schedules'!K362 -> 8531.4012 | L8: ='03 Schedules'!L362 -> 8915.3142 | N8: H8
C9: Revenue growth | E9: =E8/D8-1 -> 0.090782678 | F9: =F8/E8-1 -> 0.11420506 | G9: =G8/F8-1 -> 0.1280136 | H9: ='03 Schedules'!H363 -> 0.07 | I9: ='03 Schedules'!I363 -> 0.06 | J9: ='03 Schedules'!J363 -> 0.055 | K9: ='03 Schedules'!K363 -> 0.05 | L9: ='03 Schedules'!L363 -> 0.045 | N9: H9
C10: Cost of sales | D10: -2827.7 | E10: -3034.5 | F10: -3456.5 | G10: -3847.5 | H10: ='03 Schedules'!H364 -> -4046.9509 | I10: ='03 Schedules'!I364 -> -4297.4695 | J10: ='03 Schedules'!J364 -> -4541.9555 | K10: ='03 Schedules'!K364 -> -4777.5847 | L10: ='03 Schedules'!L364 -> -4992.576 | N10: H10
C11: Cost of sales as % of Revenue | D11: =-D10/D8 -> 0.5617203 | E11: =-E10/E8 -> 0.55263158 | F11: =-F10/F8 -> 0.56496298 | G11: =-G10/G8 -> 0.55750366 | H11: ='03 Schedules'!H365 -> 0.557 | I11: ='03 Schedules'!I365 -> 0.558 | J11: ='03 Schedules'!J365 -> 0.559 | K11: ='03 Schedules'!K365 -> 0.56 | L11: ='03 Schedules'!L365 -> 0.56 | N11: H11
C12: Impairment losses on customer and other receivables | D12: -31 | E12: -36 | F12: -19.4 | G12: -7.1 | H12: ='03 Schedules'!H366 -> -20 | I12: ='03 Schedules'!I366 -> -21 | J12: ='03 Schedules'!J366 -> -22 | K12: ='03 Schedules'!K366 -> -23 | L12: ='03 Schedules'!L366 -> -24 | N12: H12
C13: Gross profit | D13: =SUM(D8,D10,D12) -> 2175.3 | E13: =SUM(E8,E10,E12) -> 2420.5 | F13: =SUM(F8,F10,F12) -> 2642.2 | G13: =SUM(G8,G10,G12) -> 3046.7 | H13: ='03 Schedules'!H367 -> 3198.6701 | I13: ='03 Schedules'!I367 -> 3383.0888 | J13: ='03 Schedules'!J367 -> 3561.1885 | K13: ='03 Schedules'!K367 -> 3730.8165 | L13: ='03 Schedules'!L367 -> 3898.7383 | N13: H13
C14: Gross margin | D14: =D13/D8 -> 0.43212157 | E14: =E13/E8 -> 0.44081224 | F14: =F13/F8 -> 0.4318661 | G14: =G13/G8 -> 0.44146755 | H14: ='03 Schedules'!H368 -> 0.44024731 | I14: ='03 Schedules'!I368 -> 0.43927328 | J14: ='03 Schedules'!J368 -> 0.43829236 | K14: ='03 Schedules'!K368 -> 0.43730408 | L14: ='03 Schedules'!L368 -> 0.437308 | N14: H14
C15: Distribution costs | D15: -750 | E15: -794.1 | F15: -878.8 | G15: -1027.1 | H15: ='03 Schedules'!H369 -> -1075.3119 | I15: ='03 Schedules'!I369 -> -1132.1291 | J15: ='03 Schedules'!J369 -> -1190.3336 | K15: ='03 Schedules'!K369 -> -1245.5846 | L15: ='03 Schedules'!L369 -> -1301.6359 | N15: H15
C16: Distribution costs as % of Revenue | D16: =-D15/D8 -> 0.14898689 | E16: =-E15/E8 -> 0.14461847 | F16: =-F15/F8 -> 0.14363937 | G16: =-G15/G8 -> 0.14882703 | H16: ='03 Schedules'!H370 -> 0.148 | I16: ='03 Schedules'!I370 -> 0.147 | J16: ='03 Schedules'!J370 -> 0.1465 | K16: ='03 Schedules'!K370 -> 0.146 | L16: ='03 Schedules'!L370 -> 0.146 | N16: H16
C17: Administrative expenses | D17: -481.8 | E17: -657.7 | F17: -670.6 | G17: -742.4 | H17: ='03 Schedules'!H371 -> -799.21831 | I17: ='03 Schedules'!I371 -> -839.46985 | J17: ='03 Schedules'!J371 -> -877.51555 | K17: ='03 Schedules'!K371 -> -917.12562 | L17: ='03 Schedules'!L371 -> -953.93862 | N17: H17
C18: Administrative expenses as % of Revenue | D18: =-D17/D8 -> 0.095709178 | E18: =-E17/E8 -> 0.11977782 | F18: =-F17/F8 -> 0.10960919 | G18: =-G17/G8 -> 0.10757394 | H18: ='03 Schedules'!H372 -> 0.11 | I18: ='03 Schedules'!I372 -> 0.109 | J18: ='03 Schedules'!J372 -> 0.108 | K18: ='03 Schedules'!K372 -> 0.1075 | L18: ='03 Schedules'!L372 -> 0.107 | N18: H18
C19: Other gains / (losses) | D19: -16.3 | E19: 12.3 | F19: 3.4 | G19: -3.4 | H19: ='03 Schedules'!H373 -> 0 | I19: ='03 Schedules'!I373 -> 0 | J19: ='03 Schedules'!J373 -> 0 | K19: ='03 Schedules'!K373 -> 0 | L19: ='03 Schedules'!L373 -> 0 | N19: H19
C20: Trading profit | D20: =SUM(D13,D15,D17,D19) -> 927.2 | E20: =SUM(E13,E15,E17,E19) -> 981 | F20: =SUM(F13,F15,F17,F19) -> 1096.2 | G20: =SUM(G13,G15,G17,G19) -> 1273.8 | H20: ='03 Schedules'!H374 -> 1324.1399 | I20: ='03 Schedules'!I374 -> 1411.4898 | J20: ='03 Schedules'!J374 -> 1493.3393 | K20: ='03 Schedules'!K374 -> 1568.1063 | L20: ='03 Schedules'!L374 -> 1643.1638 | N20: H20
C21: Share of results of associates and joint ventures | D21: 14.3 | E21: 6.9 | F21: 6.7 | G21: 7.9 | H21: ='03 Schedules'!H375 -> 8 | I21: ='03 Schedules'!I375 -> 8.5 | J21: ='03 Schedules'!J375 -> 9 | K21: ='03 Schedules'!K375 -> 9.5 | L21: ='03 Schedules'!L375 -> 10 | N21: H21
C22: Impairment in associates and joint ventures | D22: 0 | E22: 0 | F22: -13 | G22: -2.9 | H22: ='03 Schedules'!H376 -> 0 | I22: ='03 Schedules'!I376 -> 0 | J22: ='03 Schedules'!J376 -> 0 | K22: ='03 Schedules'!K376 -> 0 | L22: ='03 Schedules'!L376 -> 0 | N22: H22
C23: Exceptional items — curtailment loss | D23: 0 | E23: 0 | F23: -14.5 | G23: 0 | H23: ='03 Schedules'!H377 -> 0 | I23: ='03 Schedules'!I377 -> 0 | J23: ='03 Schedules'!J377 -> 0 | K23: ='03 Schedules'!K377 -> 0 | L23: ='03 Schedules'!L377 -> 0 | N23: H23
C24: Operating profit | D24: =SUM(D20:D23) -> 941.5 | E24: =SUM(E20:E23) -> 987.9 | F24: =SUM(F20:F23) -> 1075.4 | G24: =SUM(G20:G23) -> 1278.8 | H24: ='03 Schedules'!H378 -> 1332.1399 | I24: ='03 Schedules'!I378 -> 1419.9898 | J24: ='03 Schedules'!J378 -> 1502.3393 | K24: ='03 Schedules'!K378 -> 1577.6063 | L24: ='03 Schedules'!L378 -> 1653.1638 | N24: H24
C25: Gain on Reiss transaction — exceptional item | D25: 0 | E25: 108.6 | F25: 0 | G25: 0 | H25: ='03 Schedules'!H379 -> 0 | I25: ='03 Schedules'!I379 -> 0 | J25: ='03 Schedules'!J379 -> 0 | K25: ='03 Schedules'!K379 -> 0 | L25: ='03 Schedules'!L379 -> 0 | N25: H25
C26: Finance income | D26: 5.7 | E26: 6.8 | F26: 8.2 | G26: 11 | H26: ='03 Schedules'!H380 -> 5.367 | I26: ='03 Schedules'!I380 -> 5.731815 | J26: ='03 Schedules'!J380 -> 5.2 | K26: ='03 Schedules'!K380 -> 5.3 | L26: ='03 Schedules'!L380 -> 5.4 | N26: H26
C27: Finance costs | D27: -77.9 | E27: -87.5 | F27: -96.6 | G27: -97.2 | H27: ='03 Schedules'!H381 -> -89.577867 | I27: ='03 Schedules'!I381 -> -82.179817 | J27: ='03 Schedules'!J381 -> -80.48586 | K27: ='03 Schedules'!K381 -> -78.56244 | L27: ='03 Schedules'!L381 -> -76.675562 | N27: H27
C28: Profit before tax | D28: =SUM(D24:D27) -> 869.3 | E28: =SUM(E24:E27) -> 1015.8 | F28: =SUM(F24:F27) -> 987 | G28: =SUM(G24:G27) -> 1192.6 | H28: ='03 Schedules'!H382 -> 1247.929 | I28: ='03 Schedules'!I382 -> 1343.5418 | J28: ='03 Schedules'!J382 -> 1427.0535 | K28: ='03 Schedules'!K382 -> 1504.3439 | L28: ='03 Schedules'!L382 -> 1581.8882 | N28: H28
C29: Taxation | D29: -158.6 | E29: -215.3 | F29: -243.8 | G29: -294.6 | H29: ='03 Schedules'!H383 -> -311.98225 | I29: ='03 Schedules'!I383 -> -335.88546 | J29: ='03 Schedules'!J383 -> -356.76337 | K29: ='03 Schedules'!K383 -> -376.08597 | L29: ='03 Schedules'!L383 -> -395.47205 | N29: H29
C30: Net income | D30: =SUM(D28:D29) -> 710.7 | E30: =SUM(E28:E29) -> 800.5 | F30: =SUM(F28:F29) -> 743.2 | G30: =SUM(G28:G29) -> 898 | H30: ='03 Schedules'!H384 -> 935.94676 | I30: ='03 Schedules'!I384 -> 1007.6564 | J30: ='03 Schedules'!J384 -> 1070.2901 | K30: ='03 Schedules'!K384 -> 1128.2579 | L30: ='03 Schedules'!L384 -> 1186.4161 | N30: H30
C33: BALANCE SHEET | N33: Supporting schedules
C35: ASSETS
C36: Non-current assets
C37: Property, plant and equipment | D37: 644.8 | E37: 687.5 | F37: 686.4 | G37: 667.7 | H37: ='03 Schedules'!H23 -> 755.7 | I37: ='03 Schedules'!I23 -> 847.7 | J37: ='03 Schedules'!J23 -> 902.7 | K37: ='03 Schedules'!K23 -> 1004.7 | L37: ='03 Schedules'!L23 -> 1102.7 | N37: H37
C38: Intangible assets | D38: 137.1 | E38: 757.2 | F38: 735.4 | G38: 713.7 | H38: ='03 Schedules'!H44 -> 684.7 | I38: ='03 Schedules'!I44 -> 656.7 | J38: ='03 Schedules'!J44 -> 626.7 | K38: ='03 Schedules'!K44 -> 594.7 | L38: ='03 Schedules'!L44 -> 560.7 | N38: H38
C39: Right-of-use assets | D39: 662 | E39: 734.6 | F39: 737.3 | G39: 733.1 | H39: ='03 Schedules'!H74 -> 719.1 | I39: ='03 Schedules'!I74 -> 708.1 | J39: ='03 Schedules'!J74 -> 700.1 | K39: ='03 Schedules'!K74 -> 695.1 | L39: ='03 Schedules'!L74 -> 693.1 | N39: H39
C40: Associates, joint ventures and other investments | D40: 114.6 | E40: 38 | F40: 32.7 | G40: 35.2 | H40: ='03 Schedules'!H50 -> 43.2 | I40: ='03 Schedules'!I50 -> 51.7 | J40: ='03 Schedules'!J50 -> 60.7 | K40: ='03 Schedules'!K50 -> 70.2 | L40: ='03 Schedules'!L50 -> 80.2 | N40: H40
C41: Defined benefit pension asset | D41: 157.5 | E41: 59.3 | F41: 30.8 | G41: 23 | H41: ='03 Schedules'!H255 -> 23 | I41: ='03 Schedules'!I255 -> 23 | J41: ='03 Schedules'!J255 -> 23 | K41: ='03 Schedules'!K255 -> 23 | L41: ='03 Schedules'!L255 -> 23 | N41: H41
C42: Other non-current assets (financial / deferred tax) | D42: 33.3 | E42: 0 | F42: 0 | G42: 0.2 | H42: ='03 Schedules'!H256 -> 0.2 | I42: ='03 Schedules'!I256 -> 0.2 | J42: ='03 Schedules'!J256 -> 0.2 | K42: ='03 Schedules'!K256 -> 0.2 | L42: ='03 Schedules'!L256 -> 0.2 | N42: H42
C43: Total non-current assets | D43: =SUM(D37:D42) -> 1749.3 | E43: =SUM(E37:E42) -> 2276.6 | F43: =SUM(F37:F42) -> 2222.6 | G43: =SUM(G37:G42) -> 2172.9 | H43: =SUM(H37,H38,H39,H40,'03 Schedules'!H255,'03 Schedules'!H256) -> 2225.9 | I43: =SUM(I37,I38,I39,I40,'03 Schedules'!I255,'03 Schedules'!I256) -> 2287.4 | J43: =SUM(J37,J38,J39,J40,'03 Schedules'!J255,'03 Schedules'!J256) -> 2313.4 | K43: =SUM(K37,K38,K39,K40,'03 Schedules'!K255,'03 Schedules'!K256) -> 2387.9 | L43: =SUM(L37,L38,L39,L40,'03 Schedules'!L255,'03 Schedules'!L256) -> 2459.9 | N43: H43
C45: Current assets
C46: Inventories | D46: 662.2 | E46: 769 | F46: 865.2 | G46: 949.5 | H46: ='03 Schedules'!H107 -> 957.55631 | I46: ='03 Schedules'!I107 -> 1067.5526 | J46: ='03 Schedules'!J107 -> 1072.7661 | K46: ='03 Schedules'!K107 -> 1178.5888 | L46: ='03 Schedules'!L107 -> 1174.0771 | N46: H46
...

Sheet 03 Schedules
C2: Supporting schedules
C4: Return to Cover
C5: £m except percentages, days and per-share data
D6: FY2023A | E6: FY2024A | F6: FY2025A | G6: FY2026A | H6: FY2027E | I6: FY2028E | J6: FY2029E | K6: FY2030E | L6: FY2031E
C9: 1. PP&E and depreciation | N9: Next section
C10: PP&E depreciation (£m) | H10: -120 | I10: -128 | J10: -140 | K10: -155 | L10: -170 | N10: Supporting schedule input · A010
C11: PP&E disposals/other movements (£m) | H11: 0 | I11: 0 | J11: 0 | K11: 0 | L11: 0 | N11: Zero-event assumption · A011
C12: PP&E additions / CapEx (£m) | H12: ='01 Assumptions'!H24-'01 Assumptions'!H25 -> 208 | I12: ='01 Assumptions'!I24-'01 Assumptions'!I25 -> 220 | J12: ='01 Assumptions'!J24-'01 Assumptions'!J25 -> 195 | K12: ='01 Assumptions'!K24-'01 Assumptions'!K25 -> 257 | L12: ='01 Assumptions'!L24-'01 Assumptions'!L25 -> 268 | N12: Key visible driver · A013
C13: PP&E loss/(profit) on disposal (m) | H13: 0 | I13: 0 | J13: 0 | K13: 0 | L13: 0 | N13: Zero-event assumption · A049
C14: PP&E impairment charge (m) | H14: 0 | I14: 0 | J14: 0 | K14: 0 | L14: 0 | N14: Zero-event assumption · A054
C15: PP&E sale proceeds (£m) | H15: 0 | I15: 0 | J15: 0 | K15: 0 | L15: 0 | N15: Zero-event assumption · A104
C16: Held-for-sale asset proceeds (£m) | H16: 0 | I16: 0 | J16: 0 | K16: 0 | L16: 0 | N16: Zero-event assumption · A105
C17: Sale-and-leaseback proceeds (£m) | H17: 0 | I17: 0 | J17: 0 | K17: 0 | L17: 0 | N17: Zero-event assumption · A106
C19: Opening PP&E | D19: 601.1 | E19: 644.8 | F19: 687.5 | G19: 686.4 | H19: =G23 -> 667.7 | I19: =H23 -> 755.7 | J19: =I23 -> 847.7 | K19: =J23 -> 902.7 | L19: =K23 -> 1004.7
C20: PP&E additions / CapEx | D20: 207.1 | E20: 160.9 | F20: 122.9 | G20: 139.6 | H20: =H12 -> 208 | I20: =I12 -> 220 | J20: =J12 -> 195 | K20: =K12 -> 257 | L20: =L12 -> 268
C21: Depreciation | D21: -100.5 | E21: -94.9 | F21: -114.5 | G21: -116.8 | H21: =H10 -> -120 | I21: =I10 -> -128 | J21: =J10 -> -140 | K21: =K10 -> -155 | L21: =L10 -> -170
C22: Disposals / transfers / other | D22: -62.9 | E22: -23.3 | F22: -9.5 | G22: -41.5 | H22: =H11 -> 0 | I22: =I11 -> 0 | J22: =J11 -> 0 | K22: =K11 -> 0 | L22: =L11 -> 0
C23: Closing PP&E | D23: 644.8 | E23: 687.5 | F23: 686.4 | G23: 667.7 | H23: =SUM(H19:H22) -> 755.7 | I23: =SUM(I19:I22) -> 847.7 | J23: =SUM(J19:J22) -> 902.7 | K23: =SUM(K19:K22) -> 1004.7 | L23: =SUM(L19:L22) -> 1102.7
C28: 2. Intangibles and investments | N28: Next section
C29: Intangible amortisation (£m) | H29: -58 | I29: -60 | J29: -62 | K29: -64 | L29: -66 | N29: Supporting schedule input · A015
C30: Intangible disposal P&L adjustment (m) | H30: 0 | I30: 0 | J30: 0 | K30: 0 | L30: 0 | N30: Zero-event assumption · A052
C31: Intangible impairment (m) | H31: 0 | I31: 0 | J31: 0 | K31: 0 | L31: 0 | N31: Zero-event assumption · A053
C32: Intangible acquisitions / disposals / other (£m) | H32: 0 | I32: 0 | J32: 0 | K32: 0 | L32: 0 | N32: Zero-event assumption · A061
C33: Associates/JVs — new investment / dividends / other (£m) | H33: 0 | I33: 0 | J33: 0 | K33: 0 | L33: 0 | N33: Zero-event assumption · A067
C34: Loans to / from associates and JVs (£m) | H34: 0 | I34: 0 | J34: 0 | K34: 0 | L34: 0 | N34: Zero-event assumption · A107
C35: Investment in subsidiaries (£m) | H35: 0 | I35: 0 | J35: 0 | K35: 0 | L35: 0 | N35: Zero-event assumption · A108
C36: Investment in associates and JVs (£m) | H36: 0 | I36: 0 | J36: 0 | K36: 0 | L36: 0 | N36: Zero-event assumption · A109
C37: Other investing activities (£m) | H37: 0 | I37: 0 | J37: 0 | K37: 0 | L37: 0 | N37: Zero-event assumption · A110
C38: Amounts due from associates/JVs (m) | H38: 20 | I38: 20 | J38: 20 | K38: 20 | L38: 20 | N38: Temporary assumption · A016
C40: Opening intangible assets | D40: 79.3 | E40: 137.1 | F40: 757.2 | G40: 735.4 | H40: =G44 -> 713.7 | I40: =H44 -> 684.7 | J40: =I44 -> 656.7 | K40: =J44 -> 626.7 | L40: =K44 -> 594.7
C41: Intangible additions | D41: 41 | E41: 51.2 | F41: 28.2 | G41: 36.8 | H41: ='01 Assumptions'!H25 -> 29 | I41: ='01 Assumptions'!I25 -> 32 | J41: ='01 Assumptions'!J25 -> 32 | K41: ='01 Assumptions'!K25 -> 32 | L41: ='01 Assumptions'!L25 -> 32
C42: Amortisation | D42: -11.9 | E42: -36.2 | F42: -52.4 | G42: -54.8 | H42: =H29 -> -58 | I42: =I29 -> -60 | J42: =J29 -> -62 | K42: =K29 -> -64 | L42: =L29 -> -66
C43: Acquisitions / disposals / other movements | D43: 28.7 | E43: 605.1 | F43: 2.4 | G43: -3.7 | H43: =H32 -> 0 | I43: =I32 -> 0 | J43: =J32 -> 0 | K43: =K32 -> 0 | L43: =L32 -> 0
C44: Closing intangible assets | D44: 137.1 | E44: 757.2 | F44: 735.4 | G44: 713.7 | H44: =SUM(H40:H43) -> 684.7 | I44: =SUM(I40:I43) -> 656.7 | J44: =SUM(J40:J43) -> 626.7 | K44: =SUM(K40:K43) -> 594.7 | L44: =SUM(L40:L43) -> 560.7
C46: Opening associates/JVs & other investments | D46: 46.2 | E46: 114.6 | F46: 38 | G46: 32.7 | H46: =G50 -> 35.2 | I46: =H50 -> 43.2 | J46: =I50 -> 51.7 | K46: =J50 -> 60.7 | L46: =K50 -> 70.2
C47: Share of results | D47: 14.3 | E47: 6.9 | F47: 6.7 | G47: 7.9 | H47: =H375 -> 8 | I47: =I375 -> 8.5 | J47: =J375 -> 9 | K47: =K375 -> 9.5 | L47: =L375 -> 10
C48: Impairment in associates/JVs | D48: 0 | E48: 0 | F48: -13 | G48: -2.9 | H48: =H376 -> 0 | I48: =I376 -> 0 | J48: =J376 -> 0 | K48: =K376 -> 0 | L48: =L376 -> 0
C49: New investment / dividends / other | D49: 54.1 | E49: -83.5 | F49: 1 | G49: -2.5 | H49: =H33 -> 0 | I49: =I33 -> 0 | J49: =J33 -> 0 | K49: =K33 -> 0 | L49: =L33 -> 0
C50: Closing associates/JVs & other investments | D50: 114.6 | E50: 38 | F50: 32.7 | G50: 35.2 | H50: =SUM(H46:H49) -> 43.2 | I50: =SUM(I46:I49) -> 51.7 | J50: =SUM(J46:J49) -> 60.7 | K50: =SUM(K46:K49) -> 70.2 | L50: =SUM(L46:L49) -> 80.2
C55: 3. Right-of-use assets and lease liabilities | N55: Next section
...

Sheet 04 Audit & Sources
C2: Audit and sources
C4: Return to Cover
C6: Overall accounting status | E6: =IF(COUNTIFS(I10:I159,"PASS")=150,"PASS","REVIEW") -> PASS
C9: Check | D9: Period | E9: Actual | F9: Expected | G9: Difference | H9: Tolerance | I9: Status | J9: Location / interpretation
C10: Balance sheet | D10: FY2023A | E10: ='02 Model'!D53 -> 3983.8 | F10: =-'02 Model'!D73+'02 Model'!D89 -> 3983.8 | G10: =E10-F10 -> 0 | H10: 0.1 | I10: =IF(COUNT(E10:H10)<4,"UNAVAILABLE",IF(ABS(G10)<=H10,"PASS","FAIL")) -> PASS | J10: 02 Model!D91
C11: Cash-flow closing cash | D11: FY2023A | E11: ='02 Model'!D137 -> 2.7 | F11: =SUM('02 Model'!D134,'02 Model'!D133,'02 Model'!D135,'02 Model'!D136) -> 2.7 | G11: =E11-F11 -> -1.687539e-14 | H11: 0.1 | I11: =IF(COUNT(E11:H11)<4,"UNAVAILABLE",IF(ABS(G11)<=H11,"PASS","FAIL")) -> PASS | J11: 02 Model!D137
C12: Balance sheet | D12: FY2024A | E12: ='02 Model'!E53 -> 4724.3 | F12: =-'02 Model'!E73+'02 Model'!E89 -> 4724.3 | G12: =E12-F12 -> 0 | H12: 0.1 | I12: =IF(COUNT(E12:H12)<4,"UNAVAILABLE",IF(ABS(G12)<=H12,"PASS","FAIL")) -> PASS | J12: 02 Model!E91
C13: Cash-flow closing cash | D13: FY2024A | E13: ='02 Model'!E137 -> 124.3 | F13: =SUM('02 Model'!E134,'02 Model'!E133,'02 Model'!E135,'02 Model'!E136) -> 124.3 | G13: =E13-F13 -> 0 | H13: 0.1 | I13: =IF(COUNT(E13:H13)<4,"UNAVAILABLE",IF(ABS(G13)<=H13,"PASS","FAIL")) -> PASS | J13: 02 Model!E137
C14: Balance sheet | D14: FY2025A | E14: ='02 Model'!F53 -> 4872.5 | F14: =-'02 Model'!F73+'02 Model'!F89 -> 4872.5 | G14: =E14-F14 -> 0 | H14: 0.1 | I14: =IF(COUNT(E14:H14)<4,"UNAVAILABLE",IF(ABS(G14)<=H14,"PASS","FAIL")) -> PASS | J14: 02 Model!F91
C15: Cash-flow closing cash | D15: FY2025A | E15: ='02 Model'!F137 -> 171.3 | F15: =SUM('02 Model'!F134,'02 Model'!F133,'02 Model'!F135,'02 Model'!F136) -> 171.3 | G15: =E15-F15 -> 0 | H15: 0.1 | I15: =IF(COUNT(E15:H15)<4,"UNAVAILABLE",IF(ABS(G15)<=H15,"PASS","FAIL")) -> PASS | J15: 02 Model!F137
C16: Balance sheet | D16: FY2026A | E16: ='02 Model'!G53 -> 4915.3 | F16: =-'02 Model'!G73+'02 Model'!G89 -> 4915.3 | G16: =E16-F16 -> 0 | H16: 0.1 | I16: =IF(COUNT(E16:H16)<4,"UNAVAILABLE",IF(ABS(G16)<=H16,"PASS","FAIL")) -> PASS | J16: 02 Model!G91
C17: Cash-flow closing cash | D17: FY2026A | E17: ='02 Model'!G137 -> 60.2 | F17: =SUM('02 Model'!G134,'02 Model'!G133,'02 Model'!G135,'02 Model'!G136) -> 60.2 | G17: =E17-F17 -> 0 | H17: 0.1 | I17: =IF(COUNT(E17:H17)<4,"UNAVAILABLE",IF(ABS(G17)<=H17,"PASS","FAIL")) -> PASS | J17: 02 Model!G137
C18: Balance sheet | D18: FY2027E | E18: ='02 Model'!H53 -> 4981.5263 | F18: =-'02 Model'!H73+'02 Model'!H89 -> 4981.5263 | G18: =E18-F18 -> 0 | H18: 0.1 | I18: =IF(COUNT(E18:H18)<4,"UNAVAILABLE",IF(ABS(G18)<=H18,"PASS","FAIL")) -> PASS | J18: 02 Model!H91
C19: Cash-flow closing cash | D19: FY2027E | E19: ='02 Model'!H137 -> 75.748155 | F19: =SUM('02 Model'!H134,'02 Model'!H133,'02 Model'!H135,'02 Model'!H136) -> 75.748155 | G19: =E19-F19 -> 0 | H19: 0.1 | I19: =IF(COUNT(E19:H19)<4,"UNAVAILABLE",IF(ABS(G19)<=H19,"PASS","FAIL")) -> PASS | J19: 02 Model!H137
C20: Balance sheet | D20: FY2028E | E20: ='02 Model'!I53 -> 5187.0897 | F20: =-'02 Model'!I73+'02 Model'!I89 -> 5187.0897 | G20: =E20-F20 -> 0 | H20: 0.1 | I20: =IF(COUNT(E20:H20)<4,"UNAVAILABLE",IF(ABS(G20)<=H20,"PASS","FAIL")) -> PASS | J20: 02 Model!I91
C21: Cash-flow closing cash | D21: FY2028E | E21: ='02 Model'!I137 -> 64 | F21: =SUM('02 Model'!I134,'02 Model'!I133,'02 Model'!I135,'02 Model'!I136) -> 64 | G21: =E21-F21 -> 0 | H21: 0.1 | I21: =IF(COUNT(E21:H21)<4,"UNAVAILABLE",IF(ABS(G21)<=H21,"PASS","FAIL")) -> PASS | J21: 02 Model!I137
C22: Balance sheet | D22: FY2029E | E22: ='02 Model'!J53 -> 5265.5231 | F22: =-'02 Model'!J73+'02 Model'!J89 -> 5265.5231 | G22: =E22-F22 -> 0 | H22: 0.1 | I22: =IF(COUNT(E22:H22)<4,"UNAVAILABLE",IF(ABS(G22)<=H22,"PASS","FAIL")) -> PASS | J22: 02 Model!J91
C23: Cash-flow closing cash | D23: FY2029E | E23: ='02 Model'!J137 -> 64 | F23: =SUM('02 Model'!J134,'02 Model'!J133,'02 Model'!J135,'02 Model'!J136) -> 64 | G23: =E23-F23 -> 0 | H23: 0.1 | I23: =IF(COUNT(E23:H23)<4,"UNAVAILABLE",IF(ABS(G23)<=H23,"PASS","FAIL")) -> PASS | J23: 02 Model!J137
C24: Balance sheet | D24: FY2030E | E24: ='02 Model'!K53 -> 5492.4262 | F24: =-'02 Model'!K73+'02 Model'!K89 -> 5492.4262 | G24: =E24-F24 -> 0 | H24: 0.1 | I24: =IF(COUNT(E24:H24)<4,"UNAVAILABLE",IF(ABS(G24)<=H24,"PASS","FAIL")) -> PASS | J24: 02 Model!K91
C25: Cash-flow closing cash | D25: FY2030E | E25: ='02 Model'!K137 -> 64 | F25: =SUM('02 Model'!K134,'02 Model'!K133,'02 Model'!K135,'02 Model'!K136) -> 64 | G25: =E25-F25 -> 0 | H25: 0.1 | I25: =IF(COUNT(E25:H25)<4,"UNAVAILABLE",IF(ABS(G25)<=H25,"PASS","FAIL")) -> PASS | J25: 02 Model!K137
C26: Balance sheet | D26: FY2031E | E26: ='02 Model'!L53 -> 5605.8114 | F26: =-'02 Model'!L73+'02 Model'!L89 -> 5605.8114 | G26: =E26-F26 -> 0 | H26: 0.1 | I26: =IF(COUNT(E26:H26)<4,"UNAVAILABLE",IF(ABS(G26)<=H26,"PASS","FAIL")) -> PASS | J26: 02 Model!L91
C27: Cash-flow closing cash | D27: FY2031E | E27: ='02 Model'!L137 -> 64 | F27: =SUM('02 Model'!L134,'02 Model'!L133,'02 Model'!L135,'02 Model'!L136) -> 64 | G27: =E27-F27 -> 0 | H27: 0.1 | I27: =IF(COUNT(E27:H27)<4,"UNAVAILABLE",IF(ABS(G27)<=H27,"PASS","FAIL")) -> PASS | J27: 02 Model!L137
C28: Closing cash definition bridge | D28: FY2027E | E28: ='02 Model'!H51-'02 Model'!H137 -> 36 | F28: ='02 Model'!G51-'02 Model'!G137 -> 36 | G28: =E28-F28 -> 0 | H28: 0.1 | I28: =IF(COUNT(E28:H28)<4,"UNAVAILABLE",IF(ABS(G28)<=H28,"PASS","FAIL")) -> PASS | J28: Prior-period cash classification difference carried forward.
C29: Gross-debt roll-forward | D29: FY2027E | E29: ='03 Schedules'!H159 -> 696 | F29: ='03 Schedules'!H197 -> 696 | G29: =E29-F29 -> 0 | H29: 0.1 | I29: =IF(COUNT(E29:H29)<4,"UNAVAILABLE",IF(ABS(G29)<=H29,"PASS","FAIL")) -> PASS | J29: Opening gross debt + debt cash receipts / payments.
C30: Debt to balance sheet | D30: FY2027E | E30: ='03 Schedules'!H159 -> 696 | F30: =-SUM('02 Model'!H57:'02 Model'!H58)-'02 Model'!H66 -> 696 | G30: =E30-F30 -> 0 | H30: 0.1 | I30: =IF(COUNT(E30:H30)<4,"UNAVAILABLE",IF(ABS(G30)<=H30,"PASS","FAIL")) -> PASS | J30: Bank debt plus current and non-current bonds.
C31: Finance cost to schedule | D31: FY2027E | E31: =-'02 Model'!H27 -> 89.577867 | F31: ='03 Schedules'!H171+'03 Schedules'!H172+'03 Schedules'!H173 -> 89.577867 | G31: =E31-F31 -> 0 | H31: 0.1 | I31: =IF(COUNT(E31:H31)<4,"UNAVAILABLE",IF(ABS(G31)<=H31,"PASS","FAIL")) -> PASS | J31: Borrowing, lease and other finance costs.
C32: Cash interest consistency | D32: FY2027E | E32: =-'02 Model'!H123 -> 89.577867 | F32: ='03 Schedules'!H171+'03 Schedules'!H172 -> 89.577867 | G32: =E32-F32 -> 0 | H32: 0.1 | I32: =IF(COUNT(E32:H32)<4,"UNAVAILABLE",IF(ABS(G32)<=H32,"PASS","FAIL")) -> PASS | J32: Interest paid reconciles to borrowing and lease interest.
C33: Finance income | D33: FY2027E | E33: ='02 Model'!H26 -> 5.367 | F33: ='03 Schedules'!H168+'03 Schedules'!H169 -> 5.367 | G33: =E33-F33 -> 0 | H33: 0.1 | I33: =IF(COUNT(E33:H33)<4,"UNAVAILABLE",IF(ABS(G33)<=H33,"PASS","FAIL")) -> PASS | J33: Opening cash yield plus other finance income.
C34: Lease liability roll-forward | D34: FY2027E | E34: =-('02 Model'!H60+'02 Model'!H68) -> 971.789 | F34: ='03 Schedules'!H76+'03 Schedules'!H77+'03 Schedules'!H78+'03 Schedules'!H79+'03 Schedules'!H80+'03 Schedules'!H82+'03 Schedules'!H83+'03 Schedules'!H84 -> 971.789 | G34: =E34-F34 -> 0 | H34: 0.1 | I34: =IF(COUNT(E34:H34)<4,"UNAVAILABLE",IF(ABS(G34)<=H34,"PASS","FAIL")) -> PASS | J34: Opening, additions, interest, payments, disposals and FX.
C35: Lease liability split | D35: FY2027E | E35: ='03 Schedules'!H85 -> 971.789 | F35: ='03 Schedules'!H87+'03 Schedules'!H88 -> 971.789 | G35: =E35-F35 -> 0 | H35: 0.1 | I35: =IF(COUNT(E35:H35)<4,"UNAVAILABLE",IF(ABS(G35)<=H35,"PASS","FAIL")) -> PASS | J35: Current plus non-current classification.
C36: PP&E roll-forward | D36: FY2027E | E36: ='02 Model'!H37 -> 755.7 | F36: =SUM('03 Schedules'!H19:H22) -> 755.7 | G36: =E36-F36 -> 0 | H36: 0.1 | I36: =IF(COUNT(E36:H36)<4,"UNAVAILABLE",IF(ABS(G36)<=H36,"PASS","FAIL")) -> PASS | J36: Closing asset equals opening plus scheduled changes.
C37: Intangibles roll-forward | D37: FY2027E | E37: ='02 Model'!H38 -> 684.7 | F37: =SUM('03 Schedules'!H40:H43) -> 684.7 | G37: =E37-F37 -> 0 | H37: 0.1 | I37: =IF(COUNT(E37:H37)<4,"UNAVAILABLE",IF(ABS(G37)<=H37,"PASS","FAIL")) -> PASS | J37: Closing asset equals opening plus scheduled changes.
C38: ROU assets roll-forward | D38: FY2027E | E38: ='02 Model'!H39 -> 719.1 | F38: =SUM('03 Schedules'!H68:H73) -> 719.1 | G38: =E38-F38 -> 0 | H38: 0.1 | I38: =IF(COUNT(E38:H38)<4,"UNAVAILABLE",IF(ABS(G38)<=H38,"PASS","FAIL")) -> PASS | J38: Closing asset equals opening plus scheduled changes.
C39: Associates roll-forward | D39: FY2027E | E39: ='02 Model'!H40 -> 43.2 | F39: =SUM('03 Schedules'!H46:H49) -> 43.2 | G39: =E39-F39 -> 0 | H39: 0.1 | I39: =IF(COUNT(E39:H39)<4,"UNAVAILABLE",IF(ABS(G39)<=H39,"PASS","FAIL")) -> PASS | J39: Closing asset equals opening plus scheduled changes.
C40: Inventory cash reconciliation | D40: FY2027E | E40: ='03 Schedules'!H357 -> -10.356313 | F40: =-('02 Model'!H46-'02 Model'!G46)-('02 Model'!H48-'02 Model'!G48) -> -10.356313 | G40: =E40-F40 -> 0 | H40: 0.1 | I40: =IF(COUNT(E40:H40)<4,"UNAVAILABLE",IF(ABS(G40)<=H40,"PASS","FAIL")) -> PASS | J40: Inventory and right-of-return asset both included.
C41: Receivables cash reconciliation | D41: FY2027E | E41: ='03 Schedules'!H358 -> 12.678169 | F41: ='02 Model'!G47-'02 Model'!H47 -> 12.678169 | G41: =E41-F41 -> 0 | H41: 0.1 | I41: =IF(COUNT(E41:H41)<4,"UNAVAILABLE",IF(ABS(G41)<=H41,"PASS","FAIL")) -> PASS | J41: Credit book and other receivable components.
C42: Payables cash reconciliation | D42: FY2027E | E42: ='03 Schedules'!H359 -> 93.70828 | F42: ='02 Model'!G59-'02 Model'!H59 -> 93.70828 | G42: =E42-F42 -> 0 | H42: 0.1 | I42: =IF(COUNT(E42:H42)<4,"UNAVAILABLE",IF(ABS(G42)<=H42,"PASS","FAIL")) -> PASS | J42: Positive liability growth is a cash source.
C43: Receivables composition | D43: FY2027E | E43: ='02 Model'!H47 -> 1647.9218 | F43: =SUM('03 Schedules'!H113:H117) -> 1647.9218 | G43: =E43-F43 -> 0 | H43: 0.1 | I43: =IF(COUNT(E43:H43)<4,"UNAVAILABLE",IF(ABS(G43)<=H43,"PASS","FAIL")) -> PASS | J43: Sum of the component receivable accounts.
C44: Payables composition | D44: FY2027E | E44: =-'02 Model'!H59 -> 1226.1083 | F44: =SUM('03 Schedules'!H123:H129) -> 1226.1083 | G44: =E44-F44 -> 0 | H44: 0.1 | I44: =IF(COUNT(E44:H44)<4,"UNAVAILABLE",IF(ABS(G44)<=H44,"PASS","FAIL")) -> PASS | J44: Sum of the component payable accounts.
C45: Retained earnings roll-forward | D45: FY2027E | E45: ='02 Model'!H86 -> 3601.6513 | F45: =SUM('03 Schedules'!H241:H252) -> 3601.6513 | G45: =E45-F45 -> 0 | H45: 0.1 | I45: =IF(COUNT(E45:H45)<4,"UNAVAILABLE",IF(ABS(G45)<=H45,"PASS","FAIL")) -> PASS | J45: Owners’ profit, ordinary and special returns, ESOT, equity tax.
...

Sheet 05 DCF Valuation
C2: NEXT plc — base-case DCF valuation
C3: FCFF, leases treated as operating costs. £m except £ per share and shares in millions. Base Case.
C4: Return to Cover
C5: Final build: 10 September 2026. Valuation date: 7 September 2026. Market-input corroboration reviewed through 10 September; operating forecasts retain their 5 August cutoff. January balance-sheet proxies remain.
C7: Base-case DCF valuation
C8: Implied value per diluted share | G8: =G203 -> 100.96145 | H8: Intrinsic value conditional on the assumptions, not a guaranteed price.
C9: Observed market price | G9: =G52 -> 155 | H9: LSEG via Investors Chronicle, 7 Sep 2026, 16:35 BST.
C10: Implied upside / (downside) | G10: =G8/G9-1 -> -0.34863583 | H10: No input has been chosen to force agreement with the market.
C11: Enterprise value | G11: =G178 -> 12677.742 | H11: Operating value after lease cash costs.
C12: Equity value | G12: =G200 -> 11757.167
C13: Calculated WACC | G13: =G73 -> 0.098821446 | H13: CAPM and gross financial-debt weights; lease debt excluded.
C14: Terminal growth | G14: =G156 -> 0.02 | H14: Independent perpetual nominal GBP growth assumption.
C15: PV terminal value / enterprise value | G15: =G173 -> 0.51513942 | H15: A high percentage makes terminal assumptions particularly important.
C16: Calculation-check failures | G16: =COUNTIFS(G218:G241,"FAIL")+COUNTIFS(G248:G257,"FAIL") -> 0 | H16: Zero indicates that the listed calculation checks pass; valuation proxies remain judgement-sensitive.
C17: Mature incremental ROIC | G17: =G155 -> 0.2
C18: Review limitations: stale capital-structure / ESOT balances, proxy dilution and NCI values, annual FY2027 cash-flow proration, beta methodology and terminal reinvestment. See the learning guide.
C20: WACC × terminal growth — implied £ per share
C22: Formula-driven sensitivity. Columns vary terminal growth; rows vary WACC. Five-year fade held fixed; terminal reinvestment recalculates. Outlined centre is the base case.
G25: =G203 -> 100.96145 | H25: =$G$156+-2*$G$76 -> 0.01 | I25: =$G$156+-1*$G$76 -> 0.015 | J25: =$G$156+0*$G$76 -> 0.02 | K25: =$G$156+1*$G$76 -> 0.025 | L25: =$G$156+2*$G$76 -> 0.03
G26: =$G$73+-4*$G$75 -> 0.078821446 | H26: =(SUM($H$109/(1+$G26)^$H$87,$I$109/(1+$G26)^$I$87,$J$109/(1+$G26)^$J$87,$K$109/(1+$G26)^$K$87,$L$109/(1+$G26)^$L$87)+SUM($H$134*(1-$H$129/$G$155)/(1+$G26)^$H$139,$I$134*(1-$I$129/$G$155)/(1+$G26)^$I$139,$J$134*(1-$J$129/$G$155)/(1+$G26)^$J$139,$K$134*(1-$K$129/$G$155)/(1+$G26)^$K$139,$L$134*(1-$L$129/$G$155)/(1+$G26)^$L$139)+($L$130*(1+H$25)*$G$153*(1-$G$154)*(1-H$25/$G$155)/($G26-H$25)/(1+$G26)^$L$139)+$G$199)/$G$201 -> 129.48085 | I26: =(SUM($H$109/(1+$G26)^$H$87,$I$109/(1+$G26)^$I$87,$J$109/(1+$G26)^$J$87,$K$109/(1+$G26)^$K$87,$L$109/(1+$G26)^$L$87)+SUM($H$134*(1-$H$129/$G$155)/(1+$G26)^$H$139,$I$134*(1-$I$129/$G$155)/(1+$G26)^$I$139,$J$134*(1-$J$129/$G$155)/(1+$G26)^$J$139,$K$134*(1-$K$129/$G$155)/(1+$G26)^$K$139,$L$134*(1-$L$129/$G$155)/(1+$G26)^$L$139)+($L$130*(1+I$25)*$G$153*(1-$G$154)*(1-I$25/$G$155)/($G26-I$25)/(1+$G26)^$L$139)+$G$199)/$G$201 -> 133.8811 | J26: =(SUM($H$109/(1+$G26)^$H$87,$I$109/(1+$G26)^$I$87,$J$109/(1+$G26)^$J$87,$K$109/(1+$G26)^$K$87,$L$109/(1+$G26)^$L$87)+SUM($H$134*(1-$H$129/$G$155)/(1+$G26)^$H$139,$I$134*(1-$I$129/$G$155)/(1+$G26)^$I$139,$J$134*(1-$J$129/$G$155)/(1+$G26)^$J$139,$K$134*(1-$K$129/$G$155)/(1+$G26)^$K$139,$L$134*(1-$L$129/$G$155)/(1+$G26)^$L$139)+($L$130*(1+J$25)*$G$153*(1-$G$154)*(1-J$25/$G$155)/($G26-J$25)/(1+$G26)^$L$139)+$G$199)/$G$201 -> 139.00511 | K26: =(SUM($H$109/(1+$G26)^$H$87,$I$109/(1+$G26)^$I$87,$J$109/(1+$G26)^$J$87,$K$109/(1+$G26)^$K$87,$L$109/(1+$G26)^$L$87)+SUM($H$134*(1-$H$129/$G$155)/(1+$G26)^$H$139,$I$134*(1-$I$129/$G$155)/(1+$G26)^$I$139,$J$134*(1-$J$129/$G$155)/(1+$G26)^$J$139,$K$134*(1-$K$129/$G$155)/(1+$G26)^$K$139,$L$134*(1-$L$129/$G$155)/(1+$G26)^$L$139)+($L$130*(1+K$25)*$G$153*(1-$G$154)*(1-K$25/$G$155)/($G26-K$25)/(1+$G26)^$L$139)+$G$199)/$G$201 -> 145.05458 | L26: =(SUM($H$109/(1+$G26)^$H$87,$I$109/(1+$G26)^$I$87,$J$109/(1+$G26)^$J$87,$K$109/(1+$G26)^$K$87,$L$109/(1+$G26)^$L$87)+SUM($H$134*(1-$H$129/$G$155)/(1+$G26)^$H$139,$I$134*(1-$I$129/$G$155)/(1+$G26)^$I$139,$J$134*(1-$J$129/$G$155)/(1+$G26)^$J$139,$K$134*(1-$K$129/$G$155)/(1+$G26)^$K$139,$L$134*(1-$L$129/$G$155)/(1+$G26)^$L$139)+($L$130*(1+L$25)*$G$153*(1-$G$154)*(1-L$25/$G$155)/($G26-L$25)/(1+$G26)^$L$139)+$G$199)/$G$201 -> 152.31385
G27: =$G$73+-3*$G$75 -> 0.083821446 | H27: =(SUM($H$109/(1+$G27)^$H$87,$I$109/(1+$G27)^$I$87,$J$109/(1+$G27)^$J$87,$K$109/(1+$G27)^$K$87,$L$109/(1+$G27)^$L$87)+SUM($H$134*(1-$H$129/$G$155)/(1+$G27)^$H$139,$I$134*(1-$I$129/$G$155)/(1+$G27)^$I$139,$J$134*(1-$J$129/$G$155)/(1+$G27)^$J$139,$K$134*(1-$K$129/$G$155)/(1+$G27)^$K$139,$L$134*(1-$L$129/$G$155)/(1+$G27)^$L$139)+($L$130*(1+H$25)*$G$153*(1-$G$154)*(1-H$25/$G$155)/($G27-H$25)/(1+$G27)^$L$139)+$G$199)/$G$201 -> 119.64946 | I27: =(SUM($H$109/(1+$G27)^$H$87,$I$109/(1+$G27)^$I$87,$J$109/(1+$G27)^$J$87,$K$109/(1+$G27)^$K$87,$L$109/(1+$G27)^$L$87)+SUM($H$134*(1-$H$129/$G$155)/(1+$G27)^$H$139,$I$134*(1-$I$129/$G$155)/(1+$G27)^$I$139,$J$134*(1-$J$129/$G$155)/(1+$G27)^$J$139,$K$134*(1-$K$129/$G$155)/(1+$G27)^$K$139,$L$134*(1-$L$129/$G$155)/(1+$G27)^$L$139)+($L$130*(1+I$25)*$G$153*(1-$G$154)*(1-I$25/$G$155)/($G27-I$25)/(1+$G27)^$L$139)+$G$199)/$G$201 -> 123.18087 | J27: =(SUM($H$109/(1+$G27)^$H$87,$I$109/(1+$G27)^$I$87,$J$109/(1+$G27)^$J$87,$K$109/(1+$G27)^$K$87,$L$109/(1+$G27)^$L$87)+SUM($H$134*(1-$H$129/$G$155)/(1+$G27)^$H$139,$I$134*(1-$I$129/$G$155)/(1+$G27)^$I$139,$J$134*(1-$J$129/$G$155)/(1+$G27)^$J$139,$K$134*(1-$K$129/$G$155)/(1+$G27)^$K$139,$L$134*(1-$L$129/$G$155)/(1+$G27)^$L$139)+($L$130*(1+J$25)*$G$153*(1-$G$154)*(1-J$25/$G$155)/($G27-J$25)/(1+$G27)^$L$139)+$G$199)/$G$201 -> 127.24414 | K27: =(SUM($H$109/(1+$G27)^$H$87,$I$109/(1+$G27)^$I$87,$J$109/(1+$G27)^$J$87,$K$109/(1+$G27)^$K$87,$L$109/(1+$G27)^$L$87)+SUM($H$134*(1-$H$129/$G$155)/(1+$G27)^$H$139,$I$134*(1-$I$129/$G$155)/(1+$G27)^$I$139,$J$134*(1-$J$129/$G$155)/(1+$G27)^$J$139,$K$134*(1-$K$129/$G$155)/(1+$G27)^$K$139,$L$134*(1-$L$129/$G$155)/(1+$G27)^$L$139)+($L$130*(1+K$25)*$G$153*(1-$G$154)*(1-K$25/$G$155)/($G27-K$25)/(1+$G27)^$L$139)+$G$199)/$G$201 -> 131.97491 | L27: =(SUM($H$109/(1+$G27)^$H$87,$I$109/(1+$G27)^$I$87,$J$109/(1+$G27)^$J$87,$K$109/(1+$G27)^$K$87,$L$109/(1+$G27)^$L$87)+SUM($H$134*(1-$H$129/$G$155)/(1+$G27)^$H$139,$I$134*(1-$I$129/$G$155)/(1+$G27)^$I$139,$J$134*(1-$J$129/$G$155)/(1+$G27)^$J$139,$K$134*(1-$K$129/$G$155)/(1+$G27)^$K$139,$L$134*(1-$L$129/$G$155)/(1+$G27)^$L$139)+($L$130*(1+L$25)*$G$153*(1-$G$154)*(1-L$25/$G$155)/($G27-L$25)/(1+$G27)^$L$139)+$G$199)/$G$201 -> 137.55921
G28: =$G$73+-2*$G$75 -> 0.088821446 | H28: =(SUM($H$109/(1+$G28)^$H$87,$I$109/(1+$G28)^$I$87,$J$109/(1+$G28)^$J$87,$K$109/(1+$G28)^$K$87,$L$109/(1+$G28)^$L$87)+SUM($H$134*(1-$H$129/$G$155)/(1+$G28)^$H$139,$I$134*(1-$I$129/$G$155)/(1+$G28)^$I$139,$J$134*(1-$J$129/$G$155)/(1+$G28)^$J$139,$K$134*(1-$K$129/$G$155)/(1+$G28)^$K$139,$L$134*(1-$L$129/$G$155)/(1+$G28)^$L$139)+($L$130*(1+H$25)*$G$153*(1-$G$154)*(1-H$25/$G$155)/($G28-H$25)/(1+$G28)^$L$139)+$G$199)/$G$201 -> 111.08487 | I28: =(SUM($H$109/(1+$G28)^$H$87,$I$109/(1+$G28)^$I$87,$J$109/(1+$G28)^$J$87,$K$109/(1+$G28)^$K$87,$L$109/(1+$G28)^$L$87)+SUM($H$134*(1-$H$129/$G$155)/(1+$G28)^$H$139,$I$134*(1-$I$129/$G$155)/(1+$G28)^$I$139,$J$134*(1-$J$129/$G$155)/(1+$G28)^$J$139,$K$134*(1-$K$129/$G$155)/(1+$G28)^$K$139,$L$134*(1-$L$129/$G$155)/(1+$G28)^$L$139)+($L$130*(1+I$25)*$G$153*(1-$G$154)*(1-I$25/$G$155)/($G28-I$25)/(1+$G28)^$L$139)+$G$199)/$G$201 -> 113.94489 | J28: =(SUM($H$109/(1+$G28)^$H$87,$I$109/(1+$G28)^$I$87,$J$109/(1+$G28)^$J$87,$K$109/(1+$G28)^$K$87,$L$109/(1+$G28)^$L$87)+SUM($H$134*(1-$H$129/$G$155)/(1+$G28)^$H$139,$I$134*(1-$I$129/$G$155)/(1+$G28)^$I$139,$J$134*(1-$J$129/$G$155)/(1+$G28)^$J$139,$K$134*(1-$K$129/$G$155)/(1+$G28)^$K$139,$L$134*(1-$L$129/$G$155)/(1+$G28)^$L$139)+($L$130*(1+J$25)*$G$153*(1-$G$154)*(1-J$25/$G$155)/($G28-J$25)/(1+$G28)^$L$139)+$G$199)/$G$201 -> 117.20143 | K28: =(SUM($H$109/(1+$G28)^$H$87,$I$109/(1+$G28)^$I$87,$J$109/(1+$G28)^$J$87,$K$109/(1+$G28)^$K$87,$L$109/(1+$G28)^$L$87)+SUM($H$134*(1-$H$129/$G$155)/(1+$G28)^$H$139,$I$134*(1-$I$129/$G$155)/(1+$G28)^$I$139,$J$134*(1-$J$129/$G$155)/(1+$G28)^$J$139,$K$134*(1-$K$129/$G$155)/(1+$G28)^$K$139,$L$134*(1-$L$129/$G$155)/(1+$G28)^$L$139)+($L$130*(1+K$25)*$G$153*(1-$G$154)*(1-K$25/$G$155)/($G28-K$25)/(1+$G28)^$L$139)+$G$199)/$G$201 -> 120.94766 | L28: =(SUM($H$109/(1+$G28)^$H$87,$I$109/(1+$G28)^$I$87,$J$109/(1+$G28)^$J$87,$K$109/(1+$G28)^$K$87,$L$109/(1+$G28)^$L$87)+SUM($H$134*(1-$H$129/$G$155)/(1+$G28)^$H$139,$I$134*(1-$I$129/$G$155)/(1+$G28)^$I$139,$J$134*(1-$J$129/$G$155)/(1+$G28)^$J$139,$K$134*(1-$K$129/$G$155)/(1+$G28)^$K$139,$L$134*(1-$L$129/$G$155)/(1+$G28)^$L$139)+($L$130*(1+L$25)*$G$153*(1-$G$154)*(1-L$25/$G$155)/($G28-L$25)/(1+$G28)^$L$139)+$G$199)/$G$201 -> 125.30848
G29: =$G$73+-1*$G$75 -> 0.093821446 | H29: =(SUM($H$109/(1+$G29)^$H$87,$I$109/(1+$G29)^$I$87,$J$109/(1+$G29)^$J$87,$K$109/(1+$G29)^$K$87,$L$109/(1+$G29)^$L$87)+SUM($H$134*(1-$H$129/$G$155)/(1+$G29)^$H$139,$I$134*(1-$I$129/$G$155)/(1+$G29)^$I$139,$J$134*(1-$J$129/$G$155)/(1+$G29)^$J$139,$K$134*(1-$K$129/$G$155)/(1+$G29)^$K$139,$L$134*(1-$L$129/$G$155)/(1+$G29)^$L$139)+($L$130*(1+H$25)*$G$153*(1-$G$154)*(1-H$25/$G$155)/($G29-H$25)/(1+$G29)^$L$139)+$G$199)/$G$201 -> 103.55958 | I29: =(SUM($H$109/(1+$G29)^$H$87,$I$109/(1+$G29)^$I$87,$J$109/(1+$G29)^$J$87,$K$109/(1+$G29)^$K$87,$L$109/(1+$G29)^$L$87)+SUM($H$134*(1-$H$129/$G$155)/(1+$G29)^$H$139,$I$134*(1-$I$129/$G$155)/(1+$G29)^$I$139,$J$134*(1-$J$129/$G$155)/(1+$G29)^$J$139,$K$134*(1-$K$129/$G$155)/(1+$G29)^$K$139,$L$134*(1-$L$129/$G$155)/(1+$G29)^$L$139)+($L$130*(1+I$25)*$G$153*(1-$G$154)*(1-I$25/$G$155)/($G29-I$25)/(1+$G29)^$L$139)+$G$199)/$G$201 -> 105.89392 | J29: =(SUM($H$109/(1+$G29)^$H$87,$I$109/(1+$G29)^$I$87,$J$109/(1+$G29)^$J$87,$K$109/(1+$G29)^$K$87,$L$109/(1+$G29)^$L$87)+SUM($H$134*(1-$H$129/$G$155)/(1+$G29)^$H$139,$I$134*(1-$I$129/$G$155)/(1+$G29)^$I$139,$J$134*(1-$J$129/$G$155)/(1+$G29)^$J$139,$K$134*(1-$K$129/$G$155)/(1+$G29)^$K$139,$L$134*(1-$L$129/$G$155)/(1+$G29)^$L$139)+($L$130*(1+J$25)*$G$153*(1-$G$154)*(1-J$25/$G$155)/($G29-J$25)/(1+$G29)^$L$139)+$G$199)/$G$201 -> 108.52746 | K29: =(SUM($H$109/(1+$G29)^$H$87,$I$109/(1+$G29)^$I$87,$J$109/(1+$G29)^$J$87,$K$109/(1+$G29)^$K$87,$L$109/(1+$G29)^$L$87)+SUM($H$134*(1-$H$129/$G$155)/(1+$G29)^$H$139,$I$134*(1-$I$129/$G$155)/(1+$G29)^$I$139,$J$134*(1-$J$129/$G$155)/(1+$G29)^$J$139,$K$134*(1-$K$129/$G$155)/(1+$G29)^$K$139,$L$134*(1-$L$129/$G$155)/(1+$G29)^$L$139)+($L$130*(1+K$25)*$G$153*(1-$G$154)*(1-K$25/$G$155)/($G29-K$25)/(1+$G29)^$L$139)+$G$199)/$G$201 -> 111.52541 | L29: =(SUM($H$109/(1+$G29)^$H$87,$I$109/(1+$G29)^$I$87,$J$109/(1+$G29)^$J$87,$K$109/(1+$G29)^$K$87,$L$109/(1+$G29)^$L$87)+SUM($H$134*(1-$H$129/$G$155)/(1+$G29)^$H$139,$I$134*(1-$I$129/$G$155)/(1+$G29)^$I$139,$J$134*(1-$J$129/$G$155)/(1+$G29)^$J$139,$K$134*(1-$K$129/$G$155)/(1+$G29)^$K$139,$L$134*(1-$L$129/$G$155)/(1+$G29)^$L$139)+($L$130*(1+L$25)*$G$153*(1-$G$154)*(1-L$25/$G$155)/($G29-L$25)/(1+$G29)^$L$139)+$G$199)/$G$201 -> 114.97341
G30: =$G$73+0*$G$75 -> 0.098821446 | H30: =(SUM($H$109/(1+$G30)^$H$87,$I$109/(1+$G30)^$I$87,$J$109/(1+$G30)^$J$87,$K$109/(1+$G30)^$K$87,$L$109/(1+$G30)^$L$87)+SUM($H$134*(1-$H$129/$G$155)/(1+$G30)^$H$139,$I$134*(1-$I$129/$G$155)/(1+$G30)^$I$139,$J$134*(1-$J$129/$G$155)/(1+$G30)^$J$139,$K$134*(1-$K$129/$G$155)/(1+$G30)^$K$139,$L$134*(1-$L$129/$G$155)/(1+$G30)^$L$139)+($L$130*(1+H$25)*$G$153*(1-$G$154)*(1-H$25/$G$155)/($G30-H$25)/(1+$G30)^$L$139)+$G$199)/$G$201 -> 96.897327 | I30: =(SUM($H$109/(1+$G30)^$H$87,$I$109/(1+$G30)^$I$87,$J$109/(1+$G30)^$J$87,$K$109/(1+$G30)^$K$87,$L$109/(1+$G30)^$L$87)+SUM($H$134*(1-$H$129/$G$155)/(1+$G30)^$H$139,$I$134*(1-$I$129/$G$155)/(1+$G30)^$I$139,$J$134*(1-$J$129/$G$155)/(1+$G30)^$J$139,$K$134*(1-$K$129/$G$155)/(1+$G30)^$K$139,$L$134*(1-$L$129/$G$155)/(1+$G30)^$L$139)+($L$130*(1+I$25)*$G$153*(1-$G$154)*(1-I$25/$G$155)/($G30-I$25)/(1+$G30)^$L$139)+$G$199)/$G$201 -> 98.815353 | J30: =(SUM($H$109/(1+$G30)^$H$87,$I$109/(1+$G30)^$I$87,$J$109/(1+$G30)^$J$87,$K$109/(1+$G30)^$K$87,$L$109/(1+$G30)^$L$87)+SUM($H$134*(1-$H$129/$G$155)/(1+$G30)^$H$139,$I$134*(1-$I$129/$G$155)/(1+$G30)^$I$139,$J$134*(1-$J$129/$G$155)/(1+$G30)^$J$139,$K$134*(1-$K$129/$G$155)/(1+$G30)^$K$139,$L$134*(1-$L$129/$G$155)/(1+$G30)^$L$139)+($L$130*(1+J$25)*$G$153*(1-$G$154)*(1-J$25/$G$155)/($G30-J$25)/(1+$G30)^$L$139)+$G$199)/$G$201 -> 100.96145 | K30: =(SUM($H$109/(1+$G30)^$H$87,$I$109/(1+$G30)^$I$87,$J$109/(1+$G30)^$J$87,$K$109/(1+$G30)^$K$87,$L$109/(1+$G30)^$L$87)+SUM($H$134*(1-$H$129/$G$155)/(1+$G30)^$H$139,$I$134*(1-$I$129/$G$155)/(1+$G30)^$I$139,$J$134*(1-$J$129/$G$155)/(1+$G30)^$J$139,$K$134*(1-$K$129/$G$155)/(1+$G30)^$K$139,$L$134*(1-$L$129/$G$155)/(1+$G30)^$L$139)+($L$130*(1+K$25)*$G$153*(1-$G$154)*(1-K$25/$G$155)/($G30-K$25)/(1+$G30)^$L$139)+$G$199)/$G$201 -> 103.38194 | L30: =(SUM($H$109/(1+$G30)^$H$87,$I$109/(1+$G30)^$I$87,$J$109/(1+$G30)^$J$87,$K$109/(1+$G30)^$K$87,$L$109/(1+$G30)^$L$87)+SUM($H$134*(1-$H$129/$G$155)/(1+$G30)^$H$139,$I$134*(1-$I$129/$G$155)/(1+$G30)^$I$139,$J$134*(1-$J$129/$G$155)/(1+$G30)^$J$139,$K$134*(1-$K$129/$G$155)/(1+$G30)^$K$139,$L$134*(1-$L$129/$G$155)/(1+$G30)^$L$139)+($L$130*(1+L$25)*$G$153*(1-$G$154)*(1-L$25/$G$155)/($G30-L$25)/(1+$G30)^$L$139)+$G$199)/$G$201 -> 106.13666
G31: =$G$73+1*$G$75 -> 0.10382145 | H31: =(SUM($H$109/(1+$G31)^$H$87,$I$109/(1+$G31)^$I$87,$J$109/(1+$G31)^$J$87,$K$109/(1+$G31)^$K$87,$L$109/(1+$G31)^$L$87)+SUM($H$134*(1-$H$129/$G$155)/(1+$G31)^$H$139,$I$134*(1-$I$129/$G$155)/(1+$G31)^$I$139,$J$134*(1-$J$129/$G$155)/(1+$G31)^$J$139,$K$134*(1-$K$129/$G$155)/(1+$G31)^$K$139,$L$134*(1-$L$129/$G$155)/(1+$G31)^$L$139)+($L$130*(1+H$25)*$G$153*(1-$G$154)*(1-H$25/$G$155)/($G31-H$25)/(1+$G31)^$L$139)+$G$199)/$G$201 -> 90.959483 | I31: =(SUM($H$109/(1+$G31)^$H$87,$I$109/(1+$G31)^$I$87,$J$109/(1+$G31)^$J$87,$K$109/(1+$G31)^$K$87,$L$109/(1+$G31)^$L$87)+SUM($H$134*(1-$H$129/$G$155)/(1+$G31)^$H$139,$I$134*(1-$I$129/$G$155)/(1+$G31)^$I$139,$J$134*(1-$J$129/$G$155)/(1+$G31)^$J$139,$K$134*(1-$K$129/$G$155)/(1+$G31)^$K$139,$L$134*(1-$L$129/$G$155)/(1+$G31)^$L$139)+($L$130*(1+I$25)*$G$153*(1-$G$154)*(1-I$25/$G$155)/($G31-I$25)/(1+$G31)^$L$139)+$G$199)/$G$201 -> 92.544484 | J31: =(SUM($H$109/(1+$G31)^$H$87,$I$109/(1+$G31)^$I$87,$J$109/(1+$G31)^$J$87,$K$109/(1+$G31)^$K$87,$L$109/(1+$G31)^$L$87)+SUM($H$134*(1-$H$129/$G$155)/(1+$G31)^$H$139,$I$134*(1-$I$129/$G$155)/(1+$G31)^$I$139,$J$134*(1-$J$129/$G$155)/(1+$G31)^$J$139,$K$134*(1-$K$129/$G$155)/(1+$G31)^$K$139,$L$134*(1-$L$129/$G$155)/(1+$G31)^$L$139)+($L$130*(1+J$25)*$G$153*(1-$G$154)*(1-J$25/$G$155)/($G31-J$25)/(1+$G31)^$L$139)+$G$199)/$G$201 -> 94.304816 | K31: =(SUM($H$109/(1+$G31)^$H$87,$I$109/(1+$G31)^$I$87,$J$109/(1+$G31)^$J$87,$K$109/(1+$G31)^$K$87,$L$109/(1+$G31)^$L$87)+SUM($H$134*(1-$H$129/$G$155)/(1+$G31)^$H$139,$I$134*(1-$I$129/$G$155)/(1+$G31)^$I$139,$J$134*(1-$J$129/$G$155)/(1+$G31)^$J$139,$K$134*(1-$K$129/$G$155)/(1+$G31)^$K$139,$L$134*(1-$L$129/$G$155)/(1+$G31)^$L$139)+($L$130*(1+K$25)*$G$153*(1-$G$154)*(1-K$25/$G$155)/($G31-K$25)/(1+$G31)^$L$139)+$G$199)/$G$201 -> 96.273843 | L31: =(SUM($H$109/(1+$G31)^$H$87,$I$109/(1+$G31)^$I$87,$J$109/(1+$G31)^$J$87,$K$109/(1+$G31)^$K$87,$L$109/(1+$G31)^$L$87)+SUM($H$134*(1-$H$129/$G$155)/(1+$G31)^$H$139,$I$134*(1-$I$129/$G$155)/(1+$G31)^$I$139,$J$134*(1-$J$129/$G$155)/(1+$G31)^$J$139,$K$134*(1-$K$129/$G$155)/(1+$G31)^$K$139,$L$134*(1-$L$129/$G$155)/(1+$G31)^$L$139)+($L$130*(1+L$25)*$G$153*(1-$G$154)*(1-L$25/$G$155)/($G31-L$25)/(1+$G31)^$L$139)+$G$199)/$G$201 -> 98.493972
G32: =$G$73+2*$G$75 -> 0.10882145 | H32: =(SUM($H$109/(1+$G32)^$H$87,$I$109/(1+$G32)^$I$87,$J$109/(1+$G32)^$J$87,$K$109/(1+$G32)^$K$87,$L$109/(1+$G32)^$L$87)+SUM($H$134*(1-$H$129/$G$155)/(1+$G32)^$H$139,$I$134*(1-$I$129/$G$155)/(1+$G32)^$I$139,$J$134*(1-$J$129/$G$155)/(1+$G32)^$J$139,$K$134*(1-$K$129/$G$155)/(1+$G32)^$K$139,$L$134*(1-$L$129/$G$155)/(1+$G32)^$L$139)+($L$130*(1+H$25)*$G$153*(1-$G$154)*(1-H$25/$G$155)/($G32-H$25)/(1+$G32)^$L$139)+$G$199)/$G$201 -> 85.635496 | I32: =(SUM($H$109/(1+$G32)^$H$87,$I$109/(1+$G32)^$I$87,$J$109/(1+$G32)^$J$87,$K$109/(1+$G32)^$K$87,$L$109/(1+$G32)^$L$87)+SUM($H$134*(1-$H$129/$G$155)/(1+$G32)^$H$139,$I$134*(1-$I$129/$G$155)/(1+$G32)^$I$139,$J$134*(1-$J$129/$G$155)/(1+$G32)^$J$139,$K$134*(1-$K$129/$G$155)/(1+$G32)^$K$139,$L$134*(1-$L$129/$G$155)/(1+$G32)^$L$139)+($L$130*(1+I$25)*$G$153*(1-$G$154)*(1-I$25/$G$155)/($G32-I$25)/(1+$G32)^$L$139)+$G$199)/$G$201 -> 86.951744 | J32: =(SUM($H$109/(1+$G32)^$H$87,$I$109/(1+$G32)^$I$87,$J$109/(1+$G32)^$J$87,$K$109/(1+$G32)^$K$87,$L$109/(1+$G32)^$L$87)+SUM($H$134*(1-$H$129/$G$155)/(1+$G32)^$H$139,$I$134*(1-$I$129/$G$155)/(1+$G32)^$I$139,$J$134*(1-$J$129/$G$155)/(1+$G32)^$J$139,$K$134*(1-$K$129/$G$155)/(1+$G32)^$K$139,$L$134*(1-$L$129/$G$155)/(1+$G32)^$L$139)+($L$130*(1+J$25)*$G$153*(1-$G$154)*(1-J$25/$G$155)/($G32-J$25)/(1+$G32)^$L$139)+$G$199)/$G$201 -> 88.403734 | K32: =(SUM($H$109/(1+$G32)^$H$87,$I$109/(1+$G32)^$I$87,$J$109/(1+$G32)^$J$87,$K$109/(1+$G32)^$K$87,$L$109/(1+$G32)^$L$87)+SUM($H$134*(1-$H$129/$G$155)/(1+$G32)^$H$139,$I$134*(1-$I$129/$G$155)/(1+$G32)^$I$139,$J$134*(1-$J$129/$G$155)/(1+$G32)^$J$139,$K$134*(1-$K$129/$G$155)/(1+$G32)^$K$139,$L$134*(1-$L$129/$G$155)/(1+$G32)^$L$139)+($L$130*(1+K$25)*$G$153*(1-$G$154)*(1-K$25/$G$155)/($G32-K$25)/(1+$G32)^$L$139)+$G$199)/$G$201 -> 90.015758 | L32: =(SUM($H$109/(1+$G32)^$H$87,$I$109/(1+$G32)^$I$87,$J$109/(1+$G32)^$J$87,$K$109/(1+$G32)^$K$87,$L$109/(1+$G32)^$L$87)+SUM($H$134*(1-$H$129/$G$155)/(1+$G32)^$H$139,$I$134*(1-$I$129/$G$155)/(1+$G32)^$I$139,$J$134*(1-$J$129/$G$155)/(1+$G32)^$J$139,$K$134*(1-$K$129/$G$155)/(1+$G32)^$K$139,$L$134*(1-$L$129/$G$155)/(1+$G32)^$L$139)+($L$130*(1+L$25)*$G$153*(1-$G$154)*(1-L$25/$G$155)/($G32-L$25)/(1+$G32)^$L$139)+$G$199)/$G$201 -> 91.818269
G33: =$G$73+3*$G$75 -> 0.11382145 | H33: =(SUM($H$109/(1+$G33)^$H$87,$I$109/(1+$G33)^$I$87,$J$109/(1+$G33)^$J$87,$K$109/(1+$G33)^$K$87,$L$109/(1+$G33)^$L$87)+SUM($H$134*(1-$H$129/$G$155)/(1+$G33)^$H$139,$I$134*(1-$I$129/$G$155)/(1+$G33)^$I$139,$J$134*(1-$J$129/$G$155)/(1+$G33)^$J$139,$K$134*(1-$K$129/$G$155)/(1+$G33)^$K$139,$L$134*(1-$L$129/$G$155)/(1+$G33)^$L$139)+($L$130*(1+H$25)*$G$153*(1-$G$154)*(1-H$25/$G$155)/($G33-H$25)/(1+$G33)^$L$139)+$G$199)/$G$201 -> 80.83614 | I33: =(SUM($H$109/(1+$G33)^$H$87,$I$109/(1+$G33)^$I$87,$J$109/(1+$G33)^$J$87,$K$109/(1+$G33)^$K$87,$L$109/(1+$G33)^$L$87)+SUM($H$134*(1-$H$129/$G$155)/(1+$G33)^$H$139,$I$134*(1-$I$129/$G$155)/(1+$G33)^$I$139,$J$134*(1-$J$129/$G$155)/(1+$G33)^$J$139,$K$134*(1-$K$129/$G$155)/(1+$G33)^$K$139,$L$134*(1-$L$129/$G$155)/(1+$G33)^$L$139)+($L$130*(1+I$25)*$G$153*(1-$G$154)*(1-I$25/$G$155)/($G33-I$25)/(1+$G33)^$L$139)+$G$199)/$G$201 -> 81.933806 | J33: =(SUM($H$109/(1+$G33)^$H$87,$I$109/(1+$G33)^$I$87,$J$109/(1+$G33)^$J$87,$K$109/(1+$G33)^$K$87,$L$109/(1+$G33)^$L$87)+SUM($H$134*(1-$H$129/$G$155)/(1+$G33)^$H$139,$I$134*(1-$I$129/$G$155)/(1+$G33)^$I$139,$J$134*(1-$J$129/$G$155)/(1+$G33)^$J$139,$K$134*(1-$K$129/$G$155)/(1+$G33)^$K$139,$L$134*(1-$L$129/$G$155)/(1+$G33)^$L$139)+($L$130*(1+J$25)*$G$153*(1-$G$154)*(1-J$25/$G$155)/($G33-J$25)/(1+$G33)^$L$139)+$G$199)/$G$201 -> 83.13717 | K33: =(SUM($H$109/(1+$G33)^$H$87,$I$109/(1+$G33)^$I$87,$J$109/(1+$G33)^$J$87,$K$109/(1+$G33)^$K$87,$L$109/(1+$G33)^$L$87)+SUM($H$134*(1-$H$129/$G$155)/(1+$G33)^$H$139,$I$134*(1-$I$129/$G$155)/(1+$G33)^$I$139,$J$134*(1-$J$129/$G$155)/(1+$G33)^$J$139,$K$134*(1-$K$129/$G$155)/(1+$G33)^$K$139,$L$134*(1-$L$129/$G$155)/(1+$G33)^$L$139)+($L$130*(1+K$25)*$G$153*(1-$G$154)*(1-K$25/$G$155)/($G33-K$25)/(1+$G33)^$L$139)+$G$199)/$G$201 -> 84.464081 | L33: =(SUM($H$109/(1+$G33)^$H$87,$I$109/(1+$G33)^$I$87,$J$109/(1+$G33)^$J$87,$K$109/(1+$G33)^$K$87,$L$109/(1+$G33)^$L$87)+SUM($H$134*(1-$H$129/$G$155)/(1+$G33)^$H$139,$I$134*(1-$I$129/$G$155)/(1+$G33)^$I$139,$J$134*(1-$J$129/$G$155)/(1+$G33)^$J$139,$K$134*(1-$K$129/$G$155)/(1+$G33)^$K$139,$L$134*(1-$L$129/$G$155)/(1+$G33)^$L$139)+($L$130*(1+L$25)*$G$153*(1-$G$154)*(1-L$25/$G$155)/($G33-L$25)/(1+$G33)^$L$139)+$G$199)/$G$201 -> 85.936649
G34: =$G$73+4*$G$75 -> 0.11882145 | H34: =(SUM($H$109/(1+$G34)^$H$87,$I$109/(1+$G34)^$I$87,$J$109/(1+$G34)^$J$87,$K$109/(1+$G34)^$K$87,$L$109/(1+$G34)^$L$87)+SUM($H$134*(1-$H$129/$G$155)/(1+$G34)^$H$139,$I$134*(1-$I$129/$G$155)/(1+$G34)^$I$139,$J$134*(1-$J$129/$G$155)/(1+$G34)^$J$139,$K$134*(1-$K$129/$G$155)/(1+$G34)^$K$139,$L$134*(1-$L$129/$G$155)/(1+$G34)^$L$139)+($L$130*(1+H$25)*$G$153*(1-$G$154)*(1-H$25/$G$155)/($G34-H$25)/(1+$G34)^$L$139)+$G$199)/$G$201 -> 76.488614 | I34: =(SUM($H$109/(1+$G34)^$H$87,$I$109/(1+$G34)^$I$87,$J$109/(1+$G34)^$J$87,$K$109/(1+$G34)^$K$87,$L$109/(1+$G34)^$L$87)+SUM($H$134*(1-$H$129/$G$155)/(1+$G34)^$H$139,$I$134*(1-$I$129/$G$155)/(1+$G34)^$I$139,$J$134*(1-$J$129/$G$155)/(1+$G34)^$J$139,$K$134*(1-$K$129/$G$155)/(1+$G34)^$K$139,$L$134*(1-$L$129/$G$155)/(1+$G34)^$L$139)+($L$130*(1+I$25)*$G$153*(1-$G$154)*(1-I$25/$G$155)/($G34-I$25)/(1+$G34)^$L$139)+$G$199)/$G$201 -> 77.407267 | J34: =(SUM($H$109/(1+$G34)^$H$87,$I$109/(1+$G34)^$I$87,$J$109/(1+$G34)^$J$87,$K$109/(1+$G34)^$K$87,$L$109/(1+$G34)^$L$87)+SUM($H$134*(1-$H$129/$G$155)/(1+$G34)^$H$139,$I$134*(1-$I$129/$G$155)/(1+$G34)^$I$139,$J$134*(1-$J$129/$G$155)/(1+$G34)^$J$139,$K$134*(1-$K$129/$G$155)/(1+$G34)^$K$139,$L$134*(1-$L$129/$G$155)/(1+$G34)^$L$139)+($L$130*(1+J$25)*$G$153*(1-$G$154)*(1-J$25/$G$155)/($G34-J$25)/(1+$G34)^$L$139)+$G$199)/$G$201 -> 78.408596 | K34: =(SUM($H$109/(1+$G34)^$H$87,$I$109/(1+$G34)^$I$87,$J$109/(1+$G34)^$J$87,$K$109/(1+$G34)^$K$87,$L$109/(1+$G34)^$L$87)+SUM($H$134*(1-$H$129/$G$155)/(1+$G34)^$H$139,$I$134*(1-$I$129/$G$155)/(1+$G34)^$I$139,$J$134*(1-$J$129/$G$155)/(1+$G34)^$J$139,$K$134*(1-$K$129/$G$155)/(1+$G34)^$K$139,$L$134*(1-$L$129/$G$155)/(1+$G34)^$L$139)+($L$130*(1+K$25)*$G$153*(1-$G$154)*(1-K$25/$G$155)/($G34-K$25)/(1+$G34)^$L$139)+$G$199)/$G$201 -> 79.505819 | L34: =(SUM($H$109/(1+$G34)^$H$87,$I$109/(1+$G34)^$I$87,$J$109/(1+$G34)^$J$87,$K$109/(1+$G34)^$K$87,$L$109/(1+$G34)^$L$87)+SUM($H$134*(1-$H$129/$G$155)/(1+$G34)^$H$139,$I$134*(1-$I$129/$G$155)/(1+$G34)^$I$139,$J$134*(1-$J$129/$G$155)/(1+$G34)^$J$139,$K$134*(1-$K$129/$G$155)/(1+$G34)^$K$139,$L$134*(1-$L$129/$G$155)/(1+$G34)^$L$139)+($L$130*(1+L$25)*$G$153*(1-$G$154)*(1-L$25/$G$155)/($G34-L$25)/(1+$G34)^$L$139)+$G$199)/$G$201 -> 80.715132
C36: No Excel What-If Data Table or captured results. All grid cells calculate dynamically from the explicit, transition and terminal cash flows.
C38: Mature incremental ROIC comparison
C40: Return on new capital | H40: 0.15 | I40: =G155 -> 0.2 | J40: 0.25
